<?xml version="1.0" ?>
<!-- =================================================================================== -->
<!-- |    This document was autogenerated by xacro from ./src/Two_Wheel_sim/urdf/Two_Wheel.xacro.urdf | -->
<!-- |    EDITING THIS FILE BY HAND IS NOT RECOMMENDED                                 | -->
<!-- =================================================================================== -->
<robot name="Two_Wheel">
  <link name="root">
    <inertial>
      <origin rpy="0 0 0" xyz="0 0 0"/>
      <mass value="1"/>
      <inertia ixx="1" ixy="0.0" ixz="0.0" iyy="1" iyz="0.0" izz="1"/>
    </inertial>
    <visual>
      <origin rpy="0.0 0.0 0.0" xyz="0.0 0.0 0.0"/>
      <geometry>
        <box size="1 1 1"/>
      </geometry>
    </visual>
    <collision>
      <origin rpy="0.0 0.0 0.0" xyz="0.0 0.0 0.0"/>
      <geometry>
        <box size="1 1 1"/>
      </geometry>
    </collision>
  </link>
  <joint name="RW_joint" type="revolute">
    <origin rpy="0.0 0.0 0.0" xyz="0.5 0 -0.5"/>
    <parent link="root"/>
    <child link="RW"/>
    <limit effort="1" velocity="1"/>
  </joint>
  <link name="RW">
    <inertial>
      <origin rpy="0.0 1.5707963267948966 0.0" xyz="0.5 0.0 0.0"/>
      <mass value="1"/>
      <inertia ixx="1" ixy="0.0" ixz="0.0" iyy="1" iyz="0.0" izz="1"/>
    </inertial>
    <visual>
      <origin rpy="0.0 1.5707963267948966 0.0" xyz="0.5 0.0 0.0"/>
      <geometry>
        <cylinder length="1" radius="1"/>
      </geometry>
    </visual>
    <collision>
      <origin rpy="0.0 1.5707963267948966 0.0" xyz="0.5 0.0 0.0"/>
      <geometry>
        <cylinder length="1" radius="1"/>
      </geometry>
    </collision>
  </link>
  <joint name="LW_joint" type="revolute">
    <origin rpy="0.0 0.0 0.0" xyz="-0.5 0 -0.5"/>
    <parent link="root"/>
    <child link="LW"/>
    <limit effort="1" velocity="1"/>
  </joint>
  <link name="LW">
    <inertial>
      <origin rpy="0.0 1.5707963267948966 0.0" xyz="-0.5 0.0 0.0"/>
      <mass value="1"/>
      <inertia ixx="1" ixy="0.0" ixz="0.0" iyy="1" iyz="0.0" izz="1"/>
    </inertial>
    <visual>
      <origin rpy="0.0 1.5707963267948966 0.0" xyz="-0.5 0.0 0.0"/>
      <geometry>
        <cylinder length="1" radius="1"/>
      </geometry>
    </visual>
    <collision>
      <origin rpy="0.0 1.5707963267948966 0.0" xyz="-0.5 0.0 0.0"/>
      <geometry>
        <cylinder length="1" radius="1"/>
      </geometry>
    </collision>
  </link>
</robot>
