<?xml version="1.0" ?>
<!-- =================================================================================== -->
<!-- |    This document was autogenerated by xacro from ./two_wheel_MPC.xacro.urdf     | -->
<!-- |    EDITING THIS FILE BY HAND IS NOT RECOMMENDED                                 | -->
<!-- =================================================================================== -->
<robot name="Two_Wheel">
  <link name="base_footprint">
    </link>
  <joint name="footprint_joint" type="fixed">
    <origin rpy="0 0 0" xyz="0 0 -0.1"/>
    <parent link="base_link"/>
    <child link="base_footprint"/>
  </joint>
  <link name="base_link">
    </link>
  <joint name="body_joint" type="fixed">
    <origin rpy="0 0 0" xyz="0 0 0.5"/>
    <parent link="base_link"/>
    <child link="body"/>
  </joint>
  <link name="body">
    <inertial>
      <origin rpy="0 0 0" xyz="0 0 0"/>
      <mass value="20"/>
      <inertia ixx="3.333333333333333" ixy="0.0" ixz="0.0" iyy="1.9333333333333333" iyz="0.0" izz="1.9333333333333333"/>
    </inertial>
    <visual>
      <origin rpy="0.0 0.0 0.0" xyz="0.0 0.0 0.0"/>
      <geometry>
        <box size="0.4 1 1"/>
      </geometry>
    </visual>
    <collision>
      <origin rpy="0.0 0.0 0.0" xyz="0.0 0.0 0.0"/>
      <geometry>
        <box size="0.4 1 1"/>
      </geometry>
    </collision>
  </link>
  <joint name="RW_joint" type="revolute">
    <origin rpy="0.0 0.0 0.0" xyz="0 0.5 -0.5"/>
    <axis xyz="0 1 0"/>
    <parent link="body"/>
    <child link="RW"/>
    <limit effort="100" lower="-100" upper="100" velocity="100"/>
  </joint>
  <link name="RW">
    <inertial>
      <origin rpy="1.5707963267948966 0.0 0.0" xyz="0.0 0.005 0.0"/>
      <mass value="0.1"/>
      <inertia ixx="0.0010008333333333336" ixy="0.0" ixz="0.0" iyy="0.0020000000000000005" iyz="0.0" izz="0.0010008333333333336"/>
    </inertial>
    <visual>
      <origin rpy="1.5707963267948966 0.0 0.0" xyz="0.0 0.005 0.0"/>
      <geometry>
        <cylinder length="0.01" radius="0.2"/>
      </geometry>
    </visual>
    <collision>
      <origin rpy="1.5707963267948966 0.0 0.0" xyz="0.0 0.005 0.0"/>
      <geometry>
        <cylinder length="0.01" radius="0.2"/>
      </geometry>
    </collision>
  </link>
  <joint name="LW_joint" type="revolute">
    <origin rpy="0.0 0.0 0.0" xyz="0 -0.5 -0.5"/>
    <axis xyz="0 1 0"/>
    <parent link="body"/>
    <child link="LW"/>
    <limit effort="100" lower="-100" upper="100" velocity="100"/>
  </joint>
  <link name="LW">
    <inertial>
      <origin rpy="1.5707963267948966 0.0 0.0" xyz="0.0 -0.005 0.0"/>
      <mass value="0.1"/>
      <inertia ixx="0.0010008333333333336" ixy="0.0" ixz="0.0" iyy="0.0020000000000000005" iyz="0.0" izz="0.0010008333333333336"/>
    </inertial>
    <visual>
      <origin rpy="1.5707963267948966 0.0 0.0" xyz="0.0 -0.005 0.0"/>
      <geometry>
        <cylinder length="0.01" radius="0.2"/>
      </geometry>
    </visual>
    <collision>
      <origin rpy="1.5707963267948966 0.0 0.0" xyz="0.0 -0.005 0.0"/>
      <geometry>
        <cylinder length="0.01" radius="0.2"/>
      </geometry>
    </collision>
  </link>
  <joint name="imu_joint" type="fixed">
    <axis xyz="1 0 0"/>
    <origin xyz="0 0 0"/>
    <parent link="body"/>
    <child link="imu_link"/>
  </joint>
  <link name="imu_link">
    <inertial>
      <mass value="0.001"/>
      <origin rpy="0 0 0" xyz="0 0 0"/>
      <inertia ixx="0.0001" ixy="0" ixz="0" iyy="0.000001" iyz="0" izz="0.0001"/>
    </inertial>
    <visual>
      <origin rpy="0 0 0" xyz="0 0 0"/>
      <geometry>
        <box size="0.001 0.001 0.001"/>
      </geometry>
    </visual>
    <collision>
      <origin rpy="0 0 0" xyz="0 0 0"/>
      <geometry>
        <box size=".001 .001 .001"/>
      </geometry>
    </collision>
  </link>
  <gazebo reference="imu_link">
    <gravity>true</gravity>
    <sensor name="imu_sensor" type="imu">
      <always_on>true</always_on>
      <update_rate>1000</update_rate>
      <visualize>true</visualize>
      <topic>imu_data</topic>
      <plugin filename="libgazebo_ros_imu_sensor.so" name="imu_plugin">
        <topicName>imu</topicName>
        <bodyName>imu_link</bodyName>
        <updateRateHZ>10.0</updateRateHZ>
        <gaussianNoise>0.0</gaussianNoise>
        <xyzOffset>0 0 0</xyzOffset>
        <rpyOffset>0 0 0</rpyOffset>
        <frameName>imu_link</frameName>
        <initialOrientationAsReference>true</initialOrientationAsReference>
      </plugin>
      <pose>0 0 0 0 0 0</pose>
    </sensor>
  </gazebo>
  <joint name="lidar_joint" type="fixed">
    <axis xyz="1 0 0"/>
    <origin xyz="0.30000000000000004 0 0"/>
    <parent link="body"/>
    <child link="lidar_link"/>
  </joint>
  <link name="lidar_link">
    <inertial>
      <mass value="0.001"/>
      <origin rpy="0 0 0" xyz="0 0 0"/>
      <inertia ixx="0.0001" ixy="0" ixz="0" iyy="0.000001" iyz="0" izz="0.0001"/>
    </inertial>
    <visual>
      <origin rpy="0 0 0" xyz="0 0 0"/>
      <geometry>
        <box size="0.001 0.001 0.001"/>
      </geometry>
    </visual>
    <collision>
      <origin rpy="0 0 0" xyz="0 0 0"/>
      <geometry>
        <box size=".001 .001 .001"/>
      </geometry>
    </collision>
  </link>
  <gazebo reference="lidar_link">
    <sensor name="lidar" type="ray">
      <always_on>true</always_on>
      <visualize>true</visualize>
      <update_rate>30</update_rate>
      <ray>
        <scan>
          <horizontal>
            <samples>100</samples>
            <resolution>1.00000</resolution>
            <min_angle>-1.57</min_angle>
            <max_angle>1.57</max_angle>
          </horizontal>
        </scan>
        <range>
          <min>0.120000</min>
          <max>35.0</max>
          <resolution>0.015000</resolution>
        </range>
        <noise>
          <type>gaussian</type>
          <mean>0.0</mean>
          <stddev>0.01</stddev>
        </noise>
      </ray>
      <plugin filename="libgazebo_ros_ray_sensor.so" name="scan">
        <ros>
          <remapping>~/out:=scan</remapping>
        </ros>
        <output_type>sensor_msgs/LaserScan</output_type>
        <frame_name>lidar_link</frame_name>
      </plugin>
    </sensor>
  </gazebo>
  <ros2_control name="TwoWheel" type="system">
    <hardware>
      <plugin>gazebo_ros2_control/GazeboSystem</plugin>
    </hardware>
    <joint name="RW_joint">
      <command_interface name="effort">
        <param name="min">-100</param>
        <param name="max">100</param>
      </command_interface>
      <!-- <command_interface name="velocity">
                <param name="min">-${speed_lim}</param>
                <param name="max">${speed_lim}</param>
            </command_interface> -->
      <state_interface name="position"/>
      <state_interface name="velocity"/>
      <state_interface name="effort"/>
    </joint>
    <joint name="LW_joint">
      <command_interface name="effort">
        <param name="min">-100</param>
        <param name="max">100</param>
      </command_interface>
      <!-- <command_interface name="velocity">
                <param name="min">-${speed_lim}</param>
                <param name="max">${speed_lim}</param>
            </command_interface> -->
      <state_interface name="position"/>
      <state_interface name="velocity"/>
      <state_interface name="effort"/>
    </joint>
    <sensor name="imu_sensor">
      <state_interface name="orientation.x"/>
      <state_interface name="orientation.y"/>
      <state_interface name="orientation.z"/>
      <state_interface name="orientation.w"/>
      <state_interface name="angular_velocity.x"/>
      <state_interface name="angular_velocity.y"/>
      <state_interface name="angular_velocity.z"/>
      <state_interface name="linear_acceleration.x"/>
      <state_interface name="linear_acceleration.y"/>
      <state_interface name="linear_acceleration.z"/>
    </sensor>
  </ros2_control>
  <gazebo>
    <plugin filename="libgazebo_ros2_control.so" name="gazebo_ros2_control">
      <robot_param>robot_description</robot_param>
      <robot_param_node>robot_state_publisher</robot_param_node>
      <!-- <parameters>/home/lorenzo/Two_Wheel/ros_foxy_ws/src/two_wheel_sim/config/controller.yaml</parameters>-->
      <parameters>/home/ubuntu/Two_Wheel/ros_foxy_ws/install/share/two_wheel_sim/config/controller_MPC.yaml</parameters>
    </plugin>
  </gazebo>
</robot>
