<?xml version="1.0"?>
<robot xmlns:xacro="http://www.ros.org/wiki/xacro" name="Two_Wheel">
    
    <xacro:property name="l_b" value="1"/>
    <xacro:property name="w_b" value="1"/>
    <xacro:property name="h_b" value="1"/>
    <xacro:property name="m_b" value="1"/>
    <xacro:property name="m_w" value="1"/>
    <xacro:property name="r_w" value="1"/>
    <xacro:property name="w_t" value="1"/>
    <xacro:property name="I_b_xx" value="1"/>
    <xacro:property name="I_b_yy" value="1"/>
    <xacro:property name="I_b_zz" value="1"/>
    <xacro:property name="I_w_xx" value="1"/>
    <xacro:property name="I_w_yy" value="1"/>
    <xacro:property name="I_w_zz" value="1"/>
    <xacro:property name="eff_lim" value="1"/>
    <xacro:property name="speed_lim" value="1"/>
    
    <link name="root">
        <inertial>
            <origin  xyz='0 0 0' rpy='0 0 0'/>
            <mass value="${m_b}"/>
            <inertia ixx="${I_b_xx}" ixy="0.0" ixz="0.0" iyy="${I_b_yy}" iyz="0.0" izz="${I_b_zz}"/>    
        </inertial>
        <visual>
            <origin xyz="0.0 0.0 0.0" rpy="0.0 0.0 0.0"/>    
            <geometry>
                <box size="${l_b} ${w_b} ${h_b}"/>
            </geometry>
        </visual>
        <collision>
            <origin xyz="0.0 0.0 0.0" rpy="0.0 0.0 0.0"/>
            <geometry>
                <box size="${l_b} ${w_b} ${h_b}"/>
            </geometry>
        </collision>
    </link>

    <joint name="RW_joint" type="revolute">
        <origin xyz="${l_b/2} 0 ${-h_b/2}" rpy="0.0 0.0 0.0"/>
        <parent link="root"/>
        <child link="RW"/>
        <limit effort="${eff_lim}" velocity="${speed_lim}"/>
    </joint>

    <link name="RW">
        <inertial>
            <origin xyz="${w_t/2} 0.0 0.0" rpy="0.0 ${pi/2} 0.0"/>
            <mass value="${m_w}"/>
            <inertia ixx="${I_w_xx}" ixy="0.0" ixz="0.0" iyy="${I_w_yy}" iyz="0.0" izz="${I_w_zz}"/>
        </inertial>
        <visual>
            <origin xyz="${w_t/2} 0.0 0.0" rpy="0.0 ${pi/2} 0.0"/>
            <geometry>
                <cylinder radius="${r_w}" length="${w_t}"/> 
            </geometry>
        </visual>
        <collision>
            <origin xyz="${w_t/2} 0.0 0.0" rpy="0.0 ${pi/2} 0.0"/>
            <geometry>
                <cylinder radius="${r_w}" length="${w_t}"/>    
            </geometry>
        </collision>
    </link>

    <joint name="LW_joint" type="revolute">
        <origin xyz="${-l_b/2} 0 ${-h_b/2}" rpy="0.0 0.0 0.0"/>
        <parent link="root"/>
        <child link="LW"/>
        <limit effort="${eff_lim}" velocity="${speed_lim}"/>
    </joint>

    <link name="LW">
        <inertial>
            <origin xyz="${-w_t/2} 0.0 0.0" rpy="0.0 ${pi/2} 0.0"/>
            <mass value="${m_w}"/>
            <inertia ixx="${I_w_xx}" ixy="0.0" ixz="0.0" iyy="${I_w_yy}" iyz="0.0" izz="${I_w_zz}"/>
        </inertial>
        <visual>
            <origin xyz="${-w_t/2} 0.0 0.0" rpy="0.0 ${pi/2} 0.0"/>
            <geometry>
                <cylinder radius="${r_w}" length="${w_t}"/> 
            </geometry>
        </visual>
        <collision>
            <origin xyz="${-w_t/2} 0.0 0.0" rpy="0.0 ${pi/2} 0.0"/>
            <geometry>
                <cylinder radius="${r_w}" length="${w_t}"/>    
            </geometry>
        </collision>
    </link>
   

   <ros2_control name="TwoWheel" type="system">
        <hardware>
            <plugin>gazebo_ros2_control/GazeboSystem</plugin>
        </hardware>
        
        <joint name="RW_joint">
            <command_interface name="effort">
                <param name="min">-50</param>
                <param name="max">50</param>
            </command_interface>
            <state_interface name="position"/>
            <state_interface name="velocity"/>
            <state_interface name="effort"/>
        </joint>

        <joint name="LW_joint">
            <command_interface name="effort">
                <param name="min">-50</param>
                <param name="max">50</param>
            </command_interface>
            <state_interface name="position"/>
            <state_interface name="velocity"/>
            <state_interface name="effort"/>
        </joint>

   </ros2_control>
</robot>